Workbook

Sheet Assumptions
A1: BaCP - NeurIPS workshop run plan: assumptions
A2: Every blue cell is an input you can change; the Run Plan recalculates from them.
A4: Source of all timing below | B4: docs/research_overview.md sec 4.3 (MEASURED, 4x RTX 5070 Ti, 8 slots)
A5: 1 U = one 250-epoch full-length run (seconds) | B5: 2050
A6: Aggregate throughput across 8 slots (U/hour) | B6: 14
A7: GPU cost ($/hour, Vast.ai) | B7: 1.603
A8: Stem-fix wall-clock multiplier (ESTIMATE - see note) | B8: 2.5 | C8: sec 4.5: maxpool->Identity multiplies MACs by 3.98. Wall-clock will rise by less than that (dataloader + overhead). 2.5 is a placeholder - REPLACE with a measured s/epoch after the stem fix.
A10: Per-script cost correction (sec 4.3: the manifest's cost_u understates BaCP by 1.95x)
A11: script | B11: multiplier | C11: basis
A12: baseline | B12: 1 | C12: A0 measured at 2050 s = definition of 1 U (script label is "baseline" in the manifest)
A13: pruning | B13: 0.95 | C13: C0 measured at 1950 s
A14: bacp | B14: 1.95 | C14: C-null measured at 4401 s vs cost_u=1.1 nominal
A16: Config cost factor (relative to resnet34/cifar10)
A17: resnet34/cifar10 = 1.0 | resnet34/cifar100 = 1.0 (same images) | resnet50/cifar10 = 1.4 (est, Bottleneck) | resnet34/svhn = 1.5 (73,257 vs 50,000 train images)
A19: WARNING
A20: All timings above predate the stem fix (sec 4.5) and were taken on 4x RTX 5070 Ti, not an A100. Re-measure s/epoch on one A0 cell before trusting any total.

Sheet Run Plan
A1: # | B1: Phase | C1: Rung | D1: What changes | E1: Question it answers | F1: Model | G1: Dataset | H1: Sparsity | I1: Seeds | J1: Script | K1: cost_u nom | L1: Script mult | M1: Cfg factor | N1: U / seed | O1: Total U | P1: Wall-hrs | Q1: Depends on | R1: Gate | S1: Status | T1: Notes
A2: PHASE 0 - Unblock (Thu 20 - Fri 21 Aug). All 8 arms launch as ONE pool. Run is ~33 min; you get the answer in under 2 hours, not 3 days.
A3: 2 | B3: PHASE 0 | C3: N1 | D3: C0 as-is, repeat | E3: reproduce the NaN on current code | F3: resnet34 | G3: cifar10 | H3: 0.999 | I3: 1 | J3: pruning | K3: 1 | L3: =IFERROR(INDEX(Assumptions!$B$12:$B$14,MATCH(J3,Assumptions!$A$12:$A$14,0)),0) -> 0.95 | M3: 1 | N3: =K3*L3*M3 -> 0.95 | O3: =N3*I3 -> 0.95 | P3: =IFERROR(O3/Assumptions!$B$6*Assumptions!$B$8,0) -> 0.16964286 | Q3: - | R3: - | S3: TODO | T3: -
A4: 3 | B4: PHASE 0 | C4: N2 | D4: AMP off (enable_mixed_precision=False) | E4: is fp16 the cause | F4: resnet34 | G4: cifar10 | H4: 0.999 | I4: 1 | J4: pruning | K4: 1 | L4: =IFERROR(INDEX(Assumptions!$B$12:$B$14,MATCH(J4,Assumptions!$A$12:$A$14,0)),0) -> 0.95 | M4: 1 | N4: =K4*L4*M4 -> 0.95 | O4: =N4*I4 -> 0.95 | P4: =IFERROR(O4/Assumptions!$B$6*Assumptions!$B$8,0) -> 0.16964286 | Q4: - | R4: - | S4: TODO | T4: trainer.py:44 - AMP is on by default and is not a protocol field
A5: 4 | B5: PHASE 0 | C5: N3 | D5: grad clip 1.0 re-enabled | E5: is the unclipped step the cause | F5: resnet34 | G5: cifar10 | H5: 0.999 | I5: 1 | J5: pruning | K5: 1 | L5: =IFERROR(INDEX(Assumptions!$B$12:$B$14,MATCH(J5,Assumptions!$A$12:$A$14,0)),0) -> 0.95 | M5: 1 | N5: =K5*L5*M5 -> 0.95 | O5: =N5*I5 -> 0.95 | P5: =IFERROR(O5/Assumptions!$B$6*Assumptions!$B$8,0) -> 0.16964286 | Q5: - | R5: - | S5: TODO | T5: training_utils.py:598 - the call is commented out
A6: 5 | B6: PHASE 0 | C6: N4 | D6: pruner moved outside the GradScaler window | E6: is mutating weights between unscale_() and step() the cause | F6: resnet34 | G6: cifar10 | H6: 0.999 | I6: 1 | J6: pruning | K6: 1 | L6: =IFERROR(INDEX(Assumptions!$B$12:$B$14,MATCH(J6,Assumptions!$A$12:$A$14,0)),0) -> 0.95 | M6: 1 | N6: =K6*L6*M6 -> 0.95 | O6: =N6*I6 -> 0.95 | P6: =IFERROR(O6/Assumptions!$B$6*Assumptions!$B$8,0) -> 0.16964286 | Q6: - | R6: - | S6: TODO | T6: training_utils.py:505,513-517 - MY PRIMARY SUSPECT
A7: 6 | B7: PHASE 0 | C7: N5 | D7: lr 0.1 -> 0.03 | E7: is the LR the cause | F7: resnet34 | G7: cifar10 | H7: 0.999 | I7: 1 | J7: pruning | K7: 1 | L7: =IFERROR(INDEX(Assumptions!$B$12:$B$14,MATCH(J7,Assumptions!$A$12:$A$14,0)),0) -> 0.95 | M7: 1 | N7: =K7*L7*M7 -> 0.95 | O7: =N7*I7 -> 0.95 | P7: =IFERROR(O7/Assumptions!$B$6*Assumptions!$B$8,0) -> 0.16964286 | Q7: - | R7: - | S7: TODO | T7: manifest.py:96, no warmup on the cosine branch
A8: 7 | B8: PHASE 0 | C8: N6 | D8: 5-epoch linear warmup | E8: is the absence of warmup the cause | F8: resnet34 | G8: cifar10 | H8: 0.999 | I8: 1 | J8: pruning | K8: 1 | L8: =IFERROR(INDEX(Assumptions!$B$12:$B$14,MATCH(J8,Assumptions!$A$12:$A$14,0)),0) -> 0.95 | M8: 1 | N8: =K8*L8*M8 -> 0.95 | O8: =N8*I8 -> 0.95 | P8: =IFERROR(O8/Assumptions!$B$6*Assumptions!$B$8,0) -> 0.16964286 | Q8: - | R8: - | S8: TODO | T8: training_utils.py:343-350
A9: 8 | B9: PHASE 0 | C9: N7 | D9: AMP off + grad clip 1.0 | E9: belt and braces - does the pair fix it | F9: resnet34 | G9: cifar10 | H9: 0.999 | I9: 1 | J9: pruning | K9: 1 | L9: =IFERROR(INDEX(Assumptions!$B$12:$B$14,MATCH(J9,Assumptions!$A$12:$A$14,0)),0) -> 0.95 | M9: 1 | N9: =K9*L9*M9 -> 0.95 | O9: =N9*I9 -> 0.95 | P9: =IFERROR(O9/Assumptions!$B$6*Assumptions!$B$8,0) -> 0.16964286 | Q9: - | R9: - | S9: TODO | T9: confirms if 2+3 interact
A10: 9 | B10: PHASE 0 | C10: N8 | D10: sparsity 0.999 -> 0.99 | E10: is this a 0.999-only pathology | F10: resnet34 | G10: cifar10 | H10: 0.999 | I10: 1 | J10: pruning | K10: 1 | L10: =IFERROR(INDEX(Assumptions!$B$12:$B$14,MATCH(J10,Assumptions!$A$12:$A$14,0)),0) -> 0.95 | M10: 1 | N10: =K10*L10*M10 -> 0.95 | O10: =N10*I10 -> 0.95 | P10: =IFERROR(O10/Assumptions!$B$6*Assumptions!$B$8,0) -> 0.16964286 | Q10: - | R10: - | S10: TODO | T10: also tells you whether to move the anchor
A11: PHASE 1 - Anchor spine (Sat 22 - Mon 24 Aug). Tier 1 exactly as manifest.py defines it. This is the paper.
A12: 11 | B12: PHASE 1 | C12: A0 | D12: no pruning at all | E12: the dense reference | F12: resnet34 | G12: cifar10 | H12: 0.999 | I12: 5 | J12: baseline | K12: 1 | L12: =IFERROR(INDEX(Assumptions!$B$12:$B$14,MATCH(J12,Assumptions!$A$12:$A$14,0)),0) -> 1 | M12: 1 | N12: =K12*L12*M12 -> 1 | O12: =N12*I12 -> 5 | P12: =IFERROR(O12/Assumptions!$B$6*Assumptions!$B$8,0) -> 0.89285714 | Q12: - | R12: - | S12: TODO | T12: 5 seeds, zero NaN so far: 91.64 +- 0.30. VOID as a final number until the stem fix.
A13: 12 | B13: PHASE 1 | C13: A2 | D13: uniform magnitude, head dense | E13: does excluding the classifier matter | F13: resnet34 | G13: cifar10 | H13: 0.999 | I13: 5 | J13: pruning | K13: 1 | L13: =IFERROR(INDEX(Assumptions!$B$12:$B$14,MATCH(J13,Assumptions!$A$12:$A$14,0)),0) -> 0.95 | M13: 1 | N13: =K13*L13*M13 -> 0.95 | O13: =N13*I13 -> 4.75 | P13: =IFERROR(O13/Assumptions!$B$6*Assumptions!$B$8,0) -> 0.84821429 | Q13: A0 | R13: - | S13: TODO | T13: Magnitude has never run at 0.999 - sec 7.9.
A14: 13 | B14: PHASE 1 | C14: A3 | D14: ERK layer-wise budget | E14: does ERK beat uniform | F14: resnet34 | G14: cifar10 | H14: 0.999 | I14: 5 | J14: pruning | K14: 1 | L14: =IFERROR(INDEX(Assumptions!$B$12:$B$14,MATCH(J14,Assumptions!$A$12:$A$14,0)),0) -> 0.95 | M14: 1 | N14: =K14*L14*M14 -> 0.95 | O14: =N14*I14 -> 4.75 | P14: =IFERROR(O14/Assumptions!$B$6*Assumptions!$B$8,0) -> 0.84821429 | Q14: A0 | R14: - | S14: TODO | T14: Implements ER-on-unrolled, not Evci's ERK - flag F8, sec 8.3a. Re-word the citation or fix the mass.
A15: 14 | B15: PHASE 1 | C15: A4 | D15: ERK + head dense | E15: closes the 2x2 | F15: resnet34 | G15: cifar10 | H15: 0.999 | I15: 5 | J15: pruning | K15: 1 | L15: =IFERROR(INDEX(Assumptions!$B$12:$B$14,MATCH(J15,Assumptions!$A$12:$A$14,0)),0) -> 0.95 | M15: 1 | N15: =K15*L15*M15 -> 0.95 | O15: =N15*I15 -> 4.75 | P15: =IFERROR(O15/Assumptions!$B$6*Assumptions!$B$8,0) -> 0.84821429 | Q15: A0 | R15: - | S15: TODO
A16: 15 | B16: PHASE 1 | C16: A5 | D16: + RigL drop-and-regrow | E16: does dynamic topology beat a static mask | F16: resnet34 | G16: cifar10 | H16: 0.999 | I16: 5 | J16: pruning | K16: 1 | L16: =IFERROR(INDEX(Assumptions!$B$12:$B$14,MATCH(J16,Assumptions!$A$12:$A$14,0)),0) -> 0.95 | M16: 1 | N16: =K16*L16*M16 -> 0.95 | O16: =N16*I16 -> 4.75 | P16: =IFERROR(O16/Assumptions!$B$6*Assumptions!$B$8,0) -> 0.84821429 | Q16: A0 | R16: - | S16: TODO | T16: The ONLY pruner exercised at scale so far.
A17: 16 | B17: PHASE 1 | C17: C-null | D17: BaCP code path, everything BaCP-specific off | E17: is the BaCP code path neutral | F17: resnet34 | G17: cifar10 | H17: 0.999 | I17: 5 | J17: bacp | K17: 1.1 | L17: =IFERROR(INDEX(Assumptions!$B$12:$B$14,MATCH(J17,Assumptions!$A$12:$A$14,0)),0) -> 1.95 | M17: 1 | N17: =K17*L17*M17 -> 2.145 | O17: =N17*I17 -> 10.725 | P17: =IFERROR(O17/Assumptions!$B$6*Assumptions!$B$8,0) -> 1.9151786 | Q17: A0 | R17: G1 | S17: TODO | T17: Cheapest, highest-information run in the plan. 5/5 seeds NaN on the last attempt.
A18: 17 | B18: PHASE 1 | C18: C0 | D18: plain supervised training on the winning substrate | E18: THE reference every later rung is measured against | F18: resnet34 | G18: cifar10 | H18: 0.999 | I18: 5 | J18: pruning | K18: 1 | L18: =IFERROR(INDEX(Assumptions!$B$12:$B$14,MATCH(J18,Assumptions!$A$12:$A$14,0)),0) -> 0.95 | M18: 1 | N18: =K18*L18*M18 -> 0.95 | O18: =N18*I18 -> 4.75 | P18: =IFERROR(O18/Assumptions!$B$6*Assumptions!$B$8,0) -> 0.84821429 | Q18: A0 | R18: - | S18: TODO | T18: The arm the AAAI paper had no analogue of.
A19: 18 | B19: PHASE 1 | C19: C0b | D19: two augmented views per step, objective unchanged | E19: is a gain contrast, or just more augmentation | F19: resnet34 | G19: cifar10 | H19: 0.999 | I19: 5 | J19: bacp | K19: 1.4 | L19: =IFERROR(INDEX(Assumptions!$B$12:$B$14,MATCH(J19,Assumptions!$A$12:$A$14,0)),0) -> 1.95 | M19: 1 | N19: =K19*L19*M19 -> 2.73 | O19: =N19*I19 -> 13.65 | P19: =IFERROR(O19/Assumptions!$B$6*Assumptions!$B$8,0) -> 2.4375 | Q19: C-null | R19: - | S19: TODO | T19: Not optional. Without it 'contrast helps' and 'two views help' are not separable.
A20: 19 | B20: PHASE 1 | C20: C1 | D20: + dense-teacher logit KD | E20: does A TEACHER help at all | F20: resnet34 | G20: cifar10 | H20: 0.999 | I20: 5 | J20: bacp | K20: 1.6 | L20: =IFERROR(INDEX(Assumptions!$B$12:$B$14,MATCH(J20,Assumptions!$A$12:$A$14,0)),0) -> 1.95 | M20: 1 | N20: =K20*L20*M20 -> 3.12 | O20: =N20*I20 -> 15.6 | P20: =IFERROR(O20/Assumptions!$B$6*Assumptions!$B$8,0) -> 2.7857143 | Q20: C0b | R20: G3 | S20: TODO | T20: THE decider. If C1 ~= D2 the contrastive machinery is decoration.
A21: 20 | B21: PHASE 1 | C21: C2 | D21: logit KD -> feature matching | E21: does the LEVEL of injection matter | F21: resnet34 | G21: cifar10 | H21: 0.999 | I21: 5 | J21: bacp | K21: 1.6 | L21: =IFERROR(INDEX(Assumptions!$B$12:$B$14,MATCH(J21,Assumptions!$A$12:$A$14,0)),0) -> 1.95 | M21: 1 | N21: =K21*L21*M21 -> 3.12 | O21: =N21*I21 -> 15.6 | P21: =IFERROR(O21/Assumptions!$B$6*Assumptions!$B$8,0) -> 2.7857143 | Q21: C1 | R21: G3 | S21: TODO
A22: 21 | B22: PHASE 1 | C22: C3 | D22: feature regression -> contrastive form (FiC) | E22: does the CONTRASTIVE FORM matter | F22: resnet34 | G22: cifar10 | H22: 0.999 | I22: 5 | J22: bacp | K22: 1.8 | L22: =IFERROR(INDEX(Assumptions!$B$12:$B$14,MATCH(J22,Assumptions!$A$12:$A$14,0)),0) -> 1.95 | M22: 1 | N22: =K22*L22*M22 -> 3.51 | O22: =N22*I22 -> 17.55 | P22: =IFERROR(O22/Assumptions!$B$6*Assumptions!$B$8,0) -> 3.1339286 | Q22: C2 | R22: G4 | S22: TODO | T22: BROKEN AS SPECIFIED - supervised=True adds label positives AND the denominator. See Blockers B6.
A23: 22 | B23: PHASE 1 | C23: D1 | D23: + SnC snapshot teachers | E23: does SnC add anything on top of FiC | F23: resnet34 | G23: cifar10 | H23: 0.999 | I23: 5 | J23: bacp | K23: 2 | L23: =IFERROR(INDEX(Assumptions!$B$12:$B$14,MATCH(J23,Assumptions!$A$12:$A$14,0)),0) -> 1.95 | M23: 1 | N23: =K23*L23*M23 -> 3.9 | O23: =N23*I23 -> 19.5 | P23: =IFERROR(O23/Assumptions!$B$6*Assumptions!$B$8,0) -> 3.4821429 | Q23: C3 | R23: G5 | S23: TODO
A24: 23 | B24: PHASE 1 | C24: D2 | D24: + PrC pretrained teacher = FULL BaCP | E24: does PrC add anything on top of FiC+SnC | F24: resnet34 | G24: cifar10 | H24: 0.999 | I24: 5 | J24: bacp | K24: 2.2 | L24: =IFERROR(INDEX(Assumptions!$B$12:$B$14,MATCH(J24,Assumptions!$A$12:$A$14,0)),0) -> 1.95 | M24: 1 | N24: =K24*L24*M24 -> 4.29 | O24: =N24*I24 -> 21.45 | P24: =IFERROR(O24/Assumptions!$B$6*Assumptions!$B$8,0) -> 3.8303571 | Q24: D1 | R24: G5 | S24: TODO | T24: PrC's teacher is RANDOMLY INITIALISED on this box. See Blockers B2 - this changes what D2 means.
A25: PHASE 2 - Transfer panel (Mon 24 - Tue 25 Aug). Four rungs only, two seeds. This is how you get breadth back without re-running the ladder.
A26: 25 | B26: PHASE 2 | C26: A0 | D26: dense reference for this cell | E26: anchor for the panel | F26: resnet34 | G26: cifar100 | H26: 0.999 | I26: 2 | J26: baseline | K26: 1 | L26: =IFERROR(INDEX(Assumptions!$B$12:$B$14,MATCH(J26,Assumptions!$A$12:$A$14,0)),0) -> 1 | M26: 1 | N26: =K26*L26*M26 -> 1 | O26: =N26*I26 -> 2 | P26: =IFERROR(O26/Assumptions!$B$6*Assumptions!$B$8,0) -> 0.35714286 | Q26: - | R26: - | S26: TODO | T26: 2nd dataset, free - same images, same loaders, transform path already works
A27: 26 | B27: PHASE 2 | C27: C0 | D27: CE only | E27: the reference | F27: resnet34 | G27: cifar100 | H27: 0.999 | I27: 2 | J27: pruning | K27: 1 | L27: =IFERROR(INDEX(Assumptions!$B$12:$B$14,MATCH(J27,Assumptions!$A$12:$A$14,0)),0) -> 0.95 | M27: 1 | N27: =K27*L27*M27 -> 0.95 | O27: =N27*I27 -> 1.9 | P27: =IFERROR(O27/Assumptions!$B$6*Assumptions!$B$8,0) -> 0.33928571 | Q27: A0 | R27: - | S27: TODO | T27: Transfer panel - report as n=2, no significance claim.
A28: 27 | B28: PHASE 2 | C28: C1 | D28: + dense-teacher logit KD | E28: does a teacher help here too | F28: resnet34 | G28: cifar100 | H28: 0.999 | I28: 2 | J28: bacp | K28: 1.6 | L28: =IFERROR(INDEX(Assumptions!$B$12:$B$14,MATCH(J28,Assumptions!$A$12:$A$14,0)),0) -> 1.95 | M28: 1 | N28: =K28*L28*M28 -> 3.12 | O28: =N28*I28 -> 6.24 | P28: =IFERROR(O28/Assumptions!$B$6*Assumptions!$B$8,0) -> 1.1142857 | Q28: C0 | R28: - | S28: TODO | T28: Transfer panel - report as n=2, no significance claim.
A29: 28 | B29: PHASE 2 | C29: C3 | D29: contrastive form (FiC) | E29: does contrast beat KD here too | F29: resnet34 | G29: cifar100 | H29: 0.999 | I29: 2 | J29: bacp | K29: 1.8 | L29: =IFERROR(INDEX(Assumptions!$B$12:$B$14,MATCH(J29,Assumptions!$A$12:$A$14,0)),0) -> 1.95 | M29: 1 | N29: =K29*L29*M29 -> 3.51 | O29: =N29*I29 -> 7.02 | P29: =IFERROR(O29/Assumptions!$B$6*Assumptions!$B$8,0) -> 1.2535714 | Q29: C1 | R29: - | S29: TODO | T29: Transfer panel - report as n=2, no significance claim.
A30: 29 | B30: PHASE 2 | C30: D2 | D30: full BaCP | E30: does the full method hold up | F30: resnet34 | G30: cifar100 | H30: 0.999 | I30: 2 | J30: bacp | K30: 2.2 | L30: =IFERROR(INDEX(Assumptions!$B$12:$B$14,MATCH(J30,Assumptions!$A$12:$A$14,0)),0) -> 1.95 | M30: 1 | N30: =K30*L30*M30 -> 4.29 | O30: =N30*I30 -> 8.58 | P30: =IFERROR(O30/Assumptions!$B$6*Assumptions!$B$8,0) -> 1.5321429 | Q30: C3 | R30: - | S30: TODO | T30: Transfer panel - report as n=2, no significance claim.
A31: 30 | B31: PHASE 2 | C31: A0 | D31: dense reference for this cell | E31: anchor for the panel | F31: resnet50 | G31: cifar10 | H31: 0.999 | I31: 2 | J31: baseline | K31: 1 | L31: =IFERROR(INDEX(Assumptions!$B$12:$B$14,MATCH(J31,Assumptions!$A$12:$A$14,0)),0) -> 1 | M31: 1.4 | N31: =K31*L31*M31 -> 1.4 | O31: =N31*I31 -> 2.8 | P31: =IFERROR(O31/Assumptions!$B$6*Assumptions!$B$8,0) -> 0.5 | Q31: - | R31: - | S31: TODO | T31: 2nd model - registered, CIFAR stem adaptation runs for model_family=='resnet'
A32: 31 | B32: PHASE 2 | C32: C0 | D32: CE only | E32: the reference | F32: resnet50 | G32: cifar10 | H32: 0.999 | I32: 2 | J32: pruning | K32: 1 | L32: =IFERROR(INDEX(Assumptions!$B$12:$B$14,MATCH(J32,Assumptions!$A$12:$A$14,0)),0) -> 0.95 | M32: 1.4 | N32: =K32*L32*M32 -> 1.33 | O32: =N32*I32 -> 2.66 | P32: =IFERROR(O32/Assumptions!$B$6*Assumptions!$B$8,0) -> 0.475 | Q32: A0 | R32: - | S32: TODO | T32: Transfer panel - report as n=2, no significance claim.
A33: 32 | B33: PHASE 2 | C33: C1 | D33: + dense-teacher logit KD | E33: does a teacher help here too | F33: resnet50 | G33: cifar10 | H33: 0.999 | I33: 2 | J33: bacp | K33: 1.6 | L33: =IFERROR(INDEX(Assumptions!$B$12:$B$14,MATCH(J33,Assumptions!$A$12:$A$14,0)),0) -> 1.95 | M33: 1.4 | N33: =K33*L33*M33 -> 4.368 | O33: =N33*I33 -> 8.736 | P33: =IFERROR(O33/Assumptions!$B$6*Assumptions!$B$8,0) -> 1.56 | Q33: C0 | R33: - | S33: TODO | T33: Transfer panel - report as n=2, no significance claim.
A34: 33 | B34: PHASE 2 | C34: C3 | D34: contrastive form (FiC) | E34: does contrast beat KD here too | F34: resnet50 | G34: cifar10 | H34: 0.999 | I34: 2 | J34: bacp | K34: 1.8 | L34: =IFERROR(INDEX(Assumptions!$B$12:$B$14,MATCH(J34,Assumptions!$A$12:$A$14,0)),0) -> 1.95 | M34: 1.4 | N34: =K34*L34*M34 -> 4.914 | O34: =N34*I34 -> 9.828 | P34: =IFERROR(O34/Assumptions!$B$6*Assumptions!$B$8,0) -> 1.755 | Q34: C1 | R34: - | S34: TODO | T34: Transfer panel - report as n=2, no significance claim.
A35: 34 | B35: PHASE 2 | C35: D2 | D35: full BaCP | E35: does the full method hold up | F35: resnet50 | G35: cifar10 | H35: 0.999 | I35: 2 | J35: bacp | K35: 2.2 | L35: =IFERROR(INDEX(Assumptions!$B$12:$B$14,MATCH(J35,Assumptions!$A$12:$A$14,0)),0) -> 1.95 | M35: 1.4 | N35: =K35*L35*M35 -> 6.006 | O35: =N35*I35 -> 12.012 | P35: =IFERROR(O35/Assumptions!$B$6*Assumptions!$B$8,0) -> 2.145 | Q35: C3 | R35: - | S35: TODO | T35: Transfer panel - report as n=2, no significance claim.
A36: 35 | B36: PHASE 2 | C36: A0 | D36: dense reference for this cell | E36: anchor for the panel | F36: resnet34 | G36: svhn | H36: 0.999 | I36: 2 | J36: baseline | K36: 1 | L36: =IFERROR(INDEX(Assumptions!$B$12:$B$14,MATCH(J36,Assumptions!$A$12:$A$14,0)),0) -> 1 | M36: 1.5 | N36: =K36*L36*M36 -> 1.5 | O36: =N36*I36 -> 3 | P36: =IFERROR(O36/Assumptions!$B$6*Assumptions!$B$8,0) -> 0.53571429 | Q36: - | R36: - | S36: TODO | T36: 3rd dataset - registered, 32x32, never run
A37: 36 | B37: PHASE 2 | C37: C0 | D37: CE only | E37: the reference | F37: resnet34 | G37: svhn | H37: 0.999 | I37: 2 | J37: pruning | K37: 1 | L37: =IFERROR(INDEX(Assumptions!$B$12:$B$14,MATCH(J37,Assumptions!$A$12:$A$14,0)),0) -> 0.95 | M37: 1.5 | N37: =K37*L37*M37 -> 1.425 | O37: =N37*I37 -> 2.85 | P37: =IFERROR(O37/Assumptions!$B$6*Assumptions!$B$8,0) -> 0.50892857 | Q37: A0 | R37: - | S37: TODO | T37: Transfer panel - report as n=2, no significance claim.
... A40: 39 | B40: PHASE 2 | C40: D2 | D40: full BaCP | E40: does the full method hold up | F40: resnet34 | G40: svhn | H40: 0.999 | I40: 2 | J40: bacp | K40: 2.2 | L40: =IFERROR(INDEX(Assumptions!$B$12:$B$14,MATCH(J40,Assumptions!$A$12:$A$14,0)),0) -> 1.95 | M40: 1.5 | N40: =K40*L40*M40 -> 6.435 | O40: =N40*I40 -> 12.87 | P40: =IFERROR(O40/Assumptions!$B$6*Assumptions!$B$8,0) -> 2.2982143 | Q40: C3 | R40: - | S40: TODO | T40: Transfer panel - report as n=2, no significance claim.
A41: PHASE 3 - Only if Phases 0-2 are done by Tue 25 Aug. Otherwise cut without regret.
A42: 41 | B42: PHASE 3 | C42: D4-noSnC | D42: SnC removed, weights renormalised to 1/3 | E42: is SnC necessary (backward) | F42: resnet34 | G42: cifar10 | H42: 0.999 | I42: 5 | J42: bacp | K42: 2.2 | L42: =IFERROR(INDEX(Assumptions!$B$12:$B$14,MATCH(J42,Assumptions!$A$12:$A$14,0)),0) -> 1.95 | M42: 1 | N42: =K42*L42*M42 -> 4.29 | O42: =N42*I42 -> 21.45 | P42: =IFERROR(O42/Assumptions!$B$6*Assumptions!$B$8,0) -> 3.8303571 | Q42: D2 | R42: - | S42: STRETCH | T42: Keep - has no forward twin, so the gap is informative.
...

Sheet Blockers
A1: ID | B1: Defect | C1: Severity | D1: Why it blocks | E1: Fix | F1: Must land by | G1: Status | H1: Note
A2: B1 (sec 8.1) | B2: Sparse training diverges to NaN at 0.999. 5/5 C-null seeds, 2/3 C0 seeds, sitting at exactly 10.0969% (chance). Cause NOT established. | C2: BLOCKER | D2: Nothing can be measured until this is fixed. Every sparse number you have is a dead run. | E2: Phase 0: 8-arm pool, ~2 hours | F2: Thu 20 Aug | G2: OPEN | H2: Do not debug this by reading code. You have 8 slots and a 33-min run. Launch all 8 hypotheses at once.
A3: B2 - NEW FINDING | B3: PrC's teacher is a RANDOMLY INITIALISED network. Every local vision weight path points at /dbfs (model_factory.py MODELS table), which does not exist on the Vast.ai box, so load_weights fails soft and init_source='random' (sec 1.1). bacp.py:488 then contrasts the student against model_pt(data2). | C3: BLOCKER | D3: D2 (= full BaCP) is currently testing 'does aligning to a random network help', not 'does pretrained knowledge help'. The paper's stated rationale for PrC - task-agnostic knowledge from pretraining - is not what the code does. This is not in your 245KB audit: 'model_pt' appears nowhere in research_overview.md. | E3: Decide one of three: (a) load torchvision ImageNet weights for model_pt, (b) drop PrC and publish D1 as the endpoint, (c) keep it and reframe PrC honestly as a random-anchor regulariser | F3: Thu 20 Aug | G3: OPEN | H3: (a) breaks the from-scratch comparability with RigL/GraNet that the anchor was chosen for. (b) is cleanest for 9 days. (c) is the most interesting paper but needs its own control.
A4: B3 (sec 8.7 D4) | B4: The contrastive path builds no validation split, so BaCP trains on 50,000 CIFAR-10 images while the CE baseline gets 40,000. | C4: BLOCKER | D4: A 25% training-data advantage sits on the headline comparison. C0 vs D2 is uninterpretable until this is fixed. Your doc marks it 'open, by design' - I disagree; 'we state it in the paper' does not survive review. | E4: Give the contrastive path the same 40k/10k split | F4: Fri 21 Aug | G4: OPEN | H4: Must land before Phase 1 launches, not after.
A5: B4 (sec 8.2) | B5: Gates G1/G3/G4/G5 are all difference-based with no collapse floor. Two arms both dead at 10.0969% give |0.00| <= 0.5 and report PASS. | C5: BLOCKER | D5: The gate that exists to prove the BaCP code path is neutral cannot tell 'identical' from 'identically broken'. This is the state your first tier-1 attempt was actually in. | E5: ~10 lines: require both arms > 100/num_classes + k*sigma, plus a NaN-loss check off the record | F5: Fri 21 Aug | G5: OPEN | H5: test_metrics_are_in_range already fails a NaN metric but only runs under pytest -m results, so it does not gate the sweep.
A6: B5 (sec 1.3.3 / M1) | B6: The CIFAR stem keeps its maxpool, so a 32x32 input reaches layer4 at 2x2. MACs are 3.98x too low. Final stage = 61.6% of the backbone, operating on four spatial positions. | C6: HIGH | D6: Invalidates A0 as a final number and every timing in sec 4.3-4.4. Fix decided, not applied. | E6: maxpool -> Identity. Zero params and zero state_dict keys change, so all checkpoints stay loadable. | F6: Fri 21 Aug | G6: OPEN | H6: Re-measure s/epoch immediately after and update Assumptions!B8, which is currently a guess.
A7: B6 (sec 8.3b) | B7: C3 does not isolate one thing. CAPContrastiveLoss is built with supervised=True AND unsupervised=True, so C3 adds the log-sum-exp denominator AND label-defined positives that C2 has no analogue of. | C7: HIGH | D7: This is the exact error the ladder exists to prevent, and it sits on gate G4 and on the paper's central claim. | E7: Run C3 with supervised=False, or insert a C3a rung between C2 and C3 | F7: Fri 21 Aug | G7: OPEN | H7: Cheapest fix is supervised=False - it keeps the rung count and makes C2->C3 genuinely one change (negatives).
A8: B7 (sec 8.8) | B8: D4-noPrC IS D1. They differ in exactly one key, experiment_type, which has no effect on training. | C8: HIGH | D8: The PrC row of the forward/backward table is zero by construction, not by measurement. Also 5 cells x 2.2 U of duplicated compute. | E8: Drop the arm; report the D1-D2 contrast in both columns | F8: Fri 21 Aug | G8: CUT IN PLAN | H8: Already cut on the Run Plan tab.
A9: B8 (sec 8.5) | B9: No gradient clipping anywhere. clip_grad_norm_ appears once, commented out (training_utils.py:598). No max_grad_norm on any config or RunRecord. | C9: HIGH | D9: A contributing fact to B1, combined with lr 0.1, no warmup, fp16 AMP on by default, and a pruner mutating weights inside the GradScaler window. | E9: Arms N3 and N7 of the Phase 0 sweep test it | F9: Thu 20 Aug | G9: OPEN | H9: Re-enabling it is a hypothesis to test, not a fix to announce.
A10: B9 (sec 8.4) | B10: resolve_checkpoint filters on status/model/dataset/method/seed only. No code_fingerprint check, no git_sha, no protocol fields. Falls back to seed=None automatically with only a printed warning. | C10: HIGH | D10: A sparse run will start from a dense checkpoint built by different source code, and every paired CI computed from that rung is overstated. Silent by construction. | E10: Compare code_fingerprint inside resolve_checkpoint; make the seed fallback opt-in | F10: Sat 22 Aug | G10: OPEN | H10: require_gate already does this exact check elsewhere in the same file - copy it.
A11: B10 (sec 8.8) | B11: Welch intervals use a hardcoded t=2.0 when scipy is absent. At df 4-8 the true values are 2.78 and 2.31. | C11: MEDIUM | D11: Unpaired Stage A intervals print up to ~28% too narrow with no warning. scipy is in requirements-dev.txt but not requirements.txt. | E11: pip install scipy on the run box | F11: Sat 22 Aug | G11: OPEN | H11: One command. Do it in the same session as the stem fix.
A12: B11 (sec 3.4 / 8.8) | B12: HEADLINE_SPARSITIES is defined in manifest.py:69 and referenced nowhere. cells() accepts sparsity= but no caller passes it. TIERS[3] claims tier 3 includes the sweep; it does not. | C12: MEDIUM | D12: The accuracy-vs-sparsity trend that all three human reviewers asked for cannot currently be produced. | E12: Write the driver that passes sparsity= through pool.py | F12: Sun 24 Aug | G12: OPEN | H12: Phase 3 on the Run Plan depends on this.
... A16: B15 (sec 8.7 D1) | B16: load_mlm_dataloaders takes no seed parameter but load_text_dataloaders calls it with seed=seed -> TypeError; the nested loader() closure then references a module global that does not exist -> NameError. | C16: MEDIUM | D16: WikiText-2 is unreachable. The MLM half of your AAAI table had no runnable code path. | E16: ~5 lines, but then you still need an MLM protocol | F16: Not this deadline | G16: CUT | H16: Drop all LM claims from the workshop paper.

Sheet Scope
A1: Item | B1: Decision | C1: Status | D1: Why | E1: What it costs you
A2: Anchor model | B2: resnet34 ONLY at 5 seeds | C2: IN | D2: Deep on one cell beats one seed across twelve. A reviewer attacks the claim, not the breadth. | E2: -
A3: 2nd model | B3: resnet50, 4-rung panel, 2 seeds | C3: IN (Phase 2) | D3: Registered, same family, CIFAR stem path already runs for model_family=='resnet'. ~11 U. | E3: Answers 'only one architecture' without re-running the ladder.
A4: 2nd/3rd dataset | B4: cifar100 + svhn, 4-rung panel, 2 seeds | C4: IN (Phase 2) | D4: Both registered and 32x32. cifar100 is free - identical loaders. ~24 U combined. | E4: Answers 'only one dataset'.
A5: Sparsity trend | B5: 0.95 / 0.99 on C0,C1,C3,D2 | C5: STRETCH (Phase 3) | D5: All three human reviewers asked for trends across pruning rates. Needs the B11 driver first. | E5: This is the single highest-value stretch item.
A6: Anchor sparsity | B6: move from 0.999 to 0.99 | C6: DECIDE FRI | D6: At 0.999 a ResNet-34 is ~21,265 weights. Comparable to CAP (97%), to your own prior table (99%), and to the literature only at 0.99. | E6: N8 of the Phase 0 sweep also tells you whether 0.999 is where the NaN lives.
A7: Stage B (DyReLU, phasing, weight sharing) | B7: OUT | C7: CUT | D7: Defect M5 on B1, and it is a different paper: 'what substrate survives extreme sparsity' is not 'does contrast beat KD'. | E7: You lose the EAST-composition claim. It was unsupported anyway (sec 7.10: every pre-fix EAST number is void).
A8: ViTs | B8: OUT | C8: CUT | D8: image_size=224 is 49x the pixels, hub download, never run under current code. | E8: You lose 'model-agnostic across CNNs and ViTs'. It is already unsupported - sec 1.7.
A9: VGG | B9: OUT | C9: CUT | D9: Defects M2 + M6. The pruning denominator excludes 92.8% of VGG-11. | E9: You lose the architecture where BaCP LOST anyway (0/9 on VGG-11/CIFAR-100 in the old table).
A10: Language models | B10: OUT | C10: CUT | D10: WikiText-2 unreachable (D1). SST-2 reachable but has no protocol and testloader IS valloader. | E10: You lose the cross-modality claim. Say so in Limitations; CAP owns NLP and you can cite that.
A11: ImageNet | B11: OUT | C11: CUT | D11: Defect D3, and not affordable regardless. | E11: Two reviewers asked for it. State it as a limitation with a number: one ResNet-50 cell is ~2.5 days on one card.
A12: Pruning-criterion-agnostic claim | B12: OUT | C12: CUT | D12: Only RigL has ever run at scale. Magnitude, SNIP, WANDA and EAST are untested at these sparsities (sec 7.9). | E12: This was one of your five claimed deltas over CAP. It cannot be re-established by the 29th.
... A14: Framing | B14: Lead with the control, not the method | C14: IN | D14: 'Does contrastive teacher alignment beat plain distillation at extreme sparsity? A controlled decomposition.' C1 is the contribution; D2 is the endpoint of the ladder, not the thesis. | E14: Survives a null result. 'BaCP beats I.P. by 2%' does not.

Sheet Reviewer map
A1: Reviewer | B1: Complaint | C1: Where it is answered now | D1: Status | E1: Note
A2: ZzNq (3, conf 4) | B2: No ablations isolating each loss term | C2: Phase 1 C1/C2/C3/D1/D2 forward + Phase 3 D4 backward | D2: COVERED | E2: The ladder is a stronger answer than the leave-one-out table they asked for.
A3: ZzNq | B3: How many snapshots, how spaced, what if you vary the count | C3: num_snapshots=2 is fixed; no K sweep is scheduled | D3: NOT COVERED | E3: One sentence in the paper stating K=2 and why. A K sweep does not fit in 9 days.
A4: ZzNq | B4: Extra cost per batch from multiple teachers - wall time | C4: sec 4.3 has it MEASURED: dense 8.2 s/ep, CE-only 7.8, BaCP 16.3. 1.95x correction. | D4: COVERED | E4: Re-measure after the stem fix, then this is a table you already own. Most papers cannot produce it.
A5: ZzNq | B5: Results only at extreme rates; want trends across sparsity | C5: Phase 3 sparsity sweep | D5: AT RISK | E5: Depends on B11. If it slips, say explicitly that you report one sparsity and why.
A6: KQsH (5, conf 3) | B6: No ImageNet-scale study | C6: Cut | D6: NOT COVERED - BY DECISION | E6: State the limitation with the compute number attached. Workshop reviewers accept a scoped claim.
A7: KQsH | B7: GPU type, training/inference time not stated | C7: sec 4.1 + 4.3 | D7: COVERED | E7: You will have a better hardware section than most accepted papers.
A8: KQsH | B8: How is text augmented for LMs | C8: Cut with the LM cells | D8: N/A | E8: But note sec 2.9's answer is good: in CAP the two views are the same tokens through two different models. Keep that framing if LMs ever return.
A9: KQsH | B9: Bold the row-wise best numbers | C9: ladder.aggregate() + the noise-floor bolding rule (sec 5.10) | D9: COVERED | E9: You have a principled bolding rule now, which is better than what they asked for.
A10: C5T6 (3, conf 4) | B10: Framework overly complex, ablations missing | C10: Phase 1 | D10: COVERED for ablations - BUT the scope grew | E10: Cutting Stage B and D4-noPrC/noCE is what actually answers 'too complex'.
A11: C5T6 | B11: Method underperforms on VGG-11 and VGG-19 | C11: VGG cut - and defect M2 means those rows never pruned what they claimed | D11: EXPLAINED, NOT FIXED | E11: Worth one honest sentence if you reference the old results at all.
A12: C5T6 | B12: No results across random seeds | C12: Phase 1 at 5 seeds; Phase 2 at 2 seeds | D12: COVERED | E12: Report Phase 2 as n=2 with no significance claim. Do not let it look like the anchor.
... A19: AI review | B19: No perplexity for MLM despite claiming it | C19: LM cells cut | D19: N/A | E19: Also: RoBERTa/DistilBERT are encoder-only, not decoder-only as your appendix says. Fix if any LM text survives.
